
<!DOCTYPE HTML>

<html lang="en" class="_theme-default">

<head>
  <meta charset="utf-8">
  <title>Exception Handling - Kotlin - W3cubDocs</title>
  
  <meta name="description" content=" Table of contents ">
  <meta name="keywords" content="exception, handling, -, kotlin">
  <meta name="HandheldFriendly" content="True">
  <meta name="MobileOptimized" content="320">
  <meta name="viewport" content="width=device-width, initial-scale=1">
  <meta name="mobile-web-app-capable" content="yes">
  
  <link rel="canonical" href="http://docs.w3cub.com/kotlin/docs/reference/coroutines/exception-handling/">
  <link href="/favicon.png" rel="icon">
  <link rel="stylesheet" type="text/css" integrity="sha256-6/DH7X+2hvUPElJfGsvzm+tgIpmM9zjbYxnpsr6gR1A=" crossorigin="anonymous" href="/assets/application-ebf0c7ed7fb686f50f12525f1acbf39beb6022998cf738db6319e9b2bea04750.css">
  <script type="text/javascript" src="/assets/application-db285287b40ed28fac520fcfd75d7d874692b647b5b5e05968c741dda5de4148.js" integrity="sha256-2yhSh7QO0o+sUg/P1119h0aStke1teBZaMdB3aXeQUg=" crossorigin="anonymous"></script>
  <script src="/json/kotlin.js"></script>
  
  <script type="text/javascript">
    var _gaq = _gaq || [];
    _gaq.push(['_setAccount', 'UA-71174418-1']);
    _gaq.push(['_trackPageview']);

    (function() {
      var ga = document.createElement('script'); ga.type = 'text/javascript'; ga.async = true;
      ga.src = ('https:' == document.location.protocol ? 'https://ssl' : 'http://www') + '.google-analytics.com/ga.js';
      var s = document.getElementsByTagName('script')[0]; s.parentNode.insertBefore(ga, s);
    })();
  </script>
  <script async src="//pagead2.googlesyndication.com/pagead/js/adsbygoogle.js"></script>
  <script>
        (adsbygoogle = window.adsbygoogle || []).push({
            google_ad_client: "ca-pub-2572770204602497",
            enable_page_level_ads: true
        });
  </script>
  <script async custom-element="amp-auto-ads"
  src="https://cdn.ampproject.org/v0/amp-auto-ads-0.1.js">
</script>


</head>

<body>
	<div class="_app">
	<header class="_header">
  
  <form class="_search">
    <input type="search" class="_search-input" placeholder="Search&hellip;" autocomplete="off" autocapitalize="off" autocorrect="off" spellcheck="false" maxlength="20">
    <a class="_search-clear"></a>
    <div class="_search-tag"></div>
  </form>
  
  <a class="_home-link" href="/" ></a>
  <a class="_menu-link"></a>
  <h1 class="_logo">
    <a href="/" class="_nav-link" title="API Documentation Browser">W3cubDocs</a>
  </h1>
  
  <span class="_logo-sub-nav">/</span><span class="_logo-sub-nav"><a href="/kotlin/" class="_nav-link" title="" style="margin-left:0;">Kotlin</a></span>
  
  <nav class="_nav">
    <a href="https://tools.w3cub.com/?_sp=docs" target="_blank" class="_nav-link ">W3cubTools</a>
    <a href="/cheatsheets/" class="_nav-link ">Cheatsheets</a>
    <a href="/about/" class="_nav-link ">About</a>
  </nav>
</header>
	<section class="_sidebar">
		<div class="_list">
			
		</div>
	</section>
	<section class="_container ">
		<div class="_content">
			<ins class="adsbygoogle"
     style="display:block"
     data-ad-client="ca-pub-2572770204602497"
     data-ad-slot="6861657091"
     data-ad-format="link"
     data-full-width-responsive="true"></ins>
<script>
     (adsbygoogle = window.adsbygoogle || []).push({});
</script>
			<div class="_page _kotlin">
				
				
<p><strong>Table of contents</strong></p>  <ul> <li>
<a href="#exception-handling">Exception handling</a> <ul> <li><a href="#exception-propagation">Exception propagation</a></li> <li><a href="#coroutineexceptionhandler">CoroutineExceptionHandler</a></li> <li><a href="#cancellation-and-exceptions">Cancellation and exceptions</a></li> <li><a href="#exceptions-aggregation">Exceptions aggregation</a></li> </ul> </li> <li>
<a href="#supervision">Supervision</a> <ul> <li><a href="#supervision-job">Supervision job</a></li> <li><a href="#supervision-scope">Supervision scope</a></li> <li><a href="#exceptions-in-supervised-coroutines">Exceptions in supervised coroutines</a></li> </ul> </li> </ul>  <h2 id="exception-handling">Exception handling</h2> <p>This section covers exception handling and cancellation on exceptions. We already know that cancelled coroutine throws <a href="https://kotlin.github.io/kotlinx.coroutines/kotlinx-coroutines-core/kotlinx.coroutines/-cancellation-exception/index.html" target="_blank">CancellationException</a> in suspension points and that it is ignored by coroutines machinery. But what happens if an exception is thrown during cancellation or multiple children of the same coroutine throw an exception?</p> <h3 id="exception-propagation">Exception propagation</h3> <p>Coroutine builders come in two flavors: propagating exceptions automatically (<a href="https://kotlin.github.io/kotlinx.coroutines/kotlinx-coroutines-core/kotlinx.coroutines/launch.html" target="_blank">launch</a> and <a href="https://kotlin.github.io/kotlinx.coroutines/kotlinx-coroutines-core/kotlinx.coroutines.channels/actor.html" target="_blank">actor</a>) or exposing them to users (<a href="https://kotlin.github.io/kotlinx.coroutines/kotlinx-coroutines-core/kotlinx.coroutines/async.html" target="_blank">async</a> and <a href="https://kotlin.github.io/kotlinx.coroutines/kotlinx-coroutines-core/kotlinx.coroutines.channels/produce.html" target="_blank">produce</a>). The former treat exceptions as unhandled, similar to Java's <code>Thread.uncaughtExceptionHandler</code>, while the latter are relying on the user to consume the final exception, for example via <a href="https://kotlin.github.io/kotlinx.coroutines/kotlinx-coroutines-core/kotlinx.coroutines/-deferred/await.html" target="_blank">await</a> or <a href="https://kotlin.github.io/kotlinx.coroutines/kotlinx-coroutines-core/kotlinx.coroutines.channels/-receive-channel/receive.html" target="_blank">receive</a> (<a href="https://kotlin.github.io/kotlinx.coroutines/kotlinx-coroutines-core/kotlinx.coroutines.channels/produce.html" target="_blank">produce</a> and <a href="https://kotlin.github.io/kotlinx.coroutines/kotlinx-coroutines-core/kotlinx.coroutines.channels/-receive-channel/receive.html" target="_blank">receive</a> are covered later in <a href="https://github.com/Kotlin/kotlinx.coroutines/blob/master/docs/channels.md" target="_blank">Channels</a> section).</p> <p>It can be demonstrated by a simple example that creates coroutines in the <a href="https://kotlin.github.io/kotlinx.coroutines/kotlinx-coroutines-core/kotlinx.coroutines/-global-scope/index.html" target="_blank">GlobalScope</a>:</p> <div class="sample" data-highlight-only="" theme="idea"> <pre>import kotlinx.coroutines.*

fun main() = runBlocking {
    val job = GlobalScope.launch {
        println("Throwing exception from launch")
        throw IndexOutOfBoundsException() // Will be printed to the console by Thread.defaultUncaughtExceptionHandler
    }
    job.join()
    println("Joined failed job")
    val deferred = GlobalScope.async {
        println("Throwing exception from async")
        throw ArithmeticException() // Nothing is printed, relying on user to call await
    }
    try {
        deferred.await()
        println("Unreached")
    } catch (e: ArithmeticException) {
        println("Caught ArithmeticException")
    }
}
</pre> </div> <blockquote> <p>You can get full code <a href="https://github.com/kotlin/kotlinx.coroutines/blob/master/kotlinx-coroutines-core/jvm/test/guide/example-exceptions-01.kt" target="_blank">here</a>.</p> </blockquote> <p>The output of this code is (with <a href="https://github.com/Kotlin/kotlinx.coroutines/blob/master/docs/coroutine-context-and-dispatchers.md#debugging-coroutines-and-threads" target="_blank">debug</a>):</p> <pre>Throwing exception from launch
Exception in thread "DefaultDispatcher-worker-2 @coroutine#2" java.lang.IndexOutOfBoundsException
Joined failed job
Throwing exception from async
Caught ArithmeticException
</pre>  <h3 id="coroutineexceptionhandler">CoroutineExceptionHandler</h3> <p>But what if one does not want to print all exceptions to the console? <a href="https://kotlin.github.io/kotlinx.coroutines/kotlinx-coroutines-core/kotlinx.coroutines/-coroutine-exception-handler/index.html" target="_blank">CoroutineExceptionHandler</a> context element is used as generic <code>catch</code> block of coroutine where custom logging or exception handling may take place. It is similar to using <a href="https://docs.oracle.com/javase/8/docs/api/java/lang/Thread.html#setUncaughtExceptionHandler(java.lang.Thread.UncaughtExceptionHandler)" target="_blank"><code>Thread.uncaughtExceptionHandler</code></a>.</p> <p>On JVM it is possible to redefine global exception handler for all coroutines by registering <a href="https://kotlin.github.io/kotlinx.coroutines/kotlinx-coroutines-core/kotlinx.coroutines/-coroutine-exception-handler/index.html" target="_blank">CoroutineExceptionHandler</a> via <a href="https://docs.oracle.com/javase/8/docs/api/java/util/ServiceLoader.html" target="_blank"><code>ServiceLoader</code></a>. Global exception handler is similar to <a href="https://docs.oracle.com/javase/8/docs/api/java/lang/Thread.html#setDefaultUncaughtExceptionHandler(java.lang.Thread.UncaughtExceptionHandler)" target="_blank"><code>Thread.defaultUncaughtExceptionHandler</code></a> which is used when no more specific handlers are registered. On Android, <code>uncaughtExceptionPreHandler</code> is installed as a global coroutine exception handler.</p> <p><a href="https://kotlin.github.io/kotlinx.coroutines/kotlinx-coroutines-core/kotlinx.coroutines/-coroutine-exception-handler/index.html" target="_blank">CoroutineExceptionHandler</a> is invoked only on exceptions which are not expected to be handled by the user, so registering it in <a href="https://kotlin.github.io/kotlinx.coroutines/kotlinx-coroutines-core/kotlinx.coroutines/async.html" target="_blank">async</a> builder and the like of it has no effect.</p> <div class="sample" data-min-compiler-version="1.3" theme="idea"> <pre>import kotlinx.coroutines.*

fun main() = runBlocking {
//sampleStart
    val handler = CoroutineExceptionHandler { _, exception -&gt; 
        println("Caught $exception") 
    }
    val job = GlobalScope.launch(handler) {
        throw AssertionError()
    }
    val deferred = GlobalScope.async(handler) {
        throw ArithmeticException() // Nothing will be printed, relying on user to call deferred.await()
    }
    joinAll(job, deferred)
//sampleEnd    
}
</pre> </div> <blockquote> <p>You can get full code <a href="https://github.com/kotlin/kotlinx.coroutines/blob/master/kotlinx-coroutines-core/jvm/test/guide/example-exceptions-02.kt" target="_blank">here</a>.</p> </blockquote> <p>The output of this code is:</p> <pre>Caught java.lang.AssertionError
</pre>  <h3 id="cancellation-and-exceptions">Cancellation and exceptions</h3> <p>Cancellation is tightly bound with exceptions. Coroutines internally use <code>CancellationException</code> for cancellation, these exceptions are ignored by all handlers, so they should be used only as the source of additional debug information, which can be obtained by <code>catch</code> block. When a coroutine is cancelled using <a href="https://kotlin.github.io/kotlinx.coroutines/kotlinx-coroutines-core/kotlinx.coroutines/-job/cancel.html" target="_blank">Job.cancel</a> without a cause, it terminates, but it does not cancel its parent. Cancelling without cause is a mechanism for parent to cancel its children without cancelling itself.</p> <div class="sample" data-min-compiler-version="1.3" theme="idea"> <pre>import kotlinx.coroutines.*

fun main() = runBlocking {
//sampleStart
    val job = launch {
        val child = launch {
            try {
                delay(Long.MAX_VALUE)
            } finally {
                println("Child is cancelled")
            }
        }
        yield()
        println("Cancelling child")
        child.cancel()
        child.join()
        yield()
        println("Parent is not cancelled")
    }
    job.join()
//sampleEnd    
}
</pre> </div> <blockquote> <p>You can get full code <a href="https://github.com/kotlin/kotlinx.coroutines/blob/master/kotlinx-coroutines-core/jvm/test/guide/example-exceptions-03.kt" target="_blank">here</a>.</p> </blockquote> <p>The output of this code is:</p> <pre>Cancelling child
Child is cancelled
Parent is not cancelled
</pre>  <p>If a coroutine encounters exception other than <code>CancellationException</code>, it cancels its parent with that exception. This behaviour cannot be overridden and is used to provide stable coroutines hierarchies for <a href="https://github.com/Kotlin/kotlinx.coroutines/blob/master/docs/composing-suspending-functions.md#structured-concurrency-with-async" target="_blank">structured concurrency</a> which do not depend on <a href="https://kotlin.github.io/kotlinx.coroutines/kotlinx-coroutines-core/kotlinx.coroutines/-coroutine-exception-handler/index.html" target="_blank">CoroutineExceptionHandler</a> implementation. The original exception is handled by the parent when all its children terminate.</p> <blockquote> <p>This also a reason why, in these examples, <a href="https://kotlin.github.io/kotlinx.coroutines/kotlinx-coroutines-core/kotlinx.coroutines/-coroutine-exception-handler/index.html" target="_blank">CoroutineExceptionHandler</a> is always installed to a coroutine that is created in <a href="https://kotlin.github.io/kotlinx.coroutines/kotlinx-coroutines-core/kotlinx.coroutines/-global-scope/index.html" target="_blank">GlobalScope</a>. It does not make sense to install an exception handler to a coroutine that is launched in the scope of the main <a href="https://kotlin.github.io/kotlinx.coroutines/kotlinx-coroutines-core/kotlinx.coroutines/run-blocking.html" target="_blank">runBlocking</a>, since the main coroutine is going to be always cancelled when its child completes with exception despite the installed handler.</p> </blockquote> <div class="sample" data-min-compiler-version="1.3" theme="idea"> <pre>import kotlinx.coroutines.*

fun main() = runBlocking {
//sampleStart
    val handler = CoroutineExceptionHandler { _, exception -&gt; 
        println("Caught $exception") 
    }
    val job = GlobalScope.launch(handler) {
        launch { // the first child
            try {
                delay(Long.MAX_VALUE)
            } finally {
                withContext(NonCancellable) {
                    println("Children are cancelled, but exception is not handled until all children terminate")
                    delay(100)
                    println("The first child finished its non cancellable block")
                }
            }
        }
        launch { // the second child
            delay(10)
            println("Second child throws an exception")
            throw ArithmeticException()
        }
    }
    job.join()
//sampleEnd    
}
</pre> </div> <blockquote> <p>You can get full code <a href="https://github.com/kotlin/kotlinx.coroutines/blob/master/kotlinx-coroutines-core/jvm/test/guide/example-exceptions-04.kt" target="_blank">here</a>.</p> </blockquote> <p>The output of this code is:</p> <pre>Second child throws an exception
Children are cancelled, but exception is not handled until all children terminate
The first child finished its non cancellable block
Caught java.lang.ArithmeticException
</pre>  <h3 id="exceptions-aggregation">Exceptions aggregation</h3> <p>What happens if multiple children of a coroutine throw an exception? The general rule is "the first exception wins", so the first thrown exception is exposed to the handler. But that may cause lost exceptions, for example if coroutine throws an exception in its <code>finally</code> block. So, additional exceptions are suppressed.</p> <blockquote> <p>One of the solutions would have been to report each exception separately, but then <a href="https://kotlin.github.io/kotlinx.coroutines/kotlinx-coroutines-core/kotlinx.coroutines/-deferred/await.html" target="_blank">Deferred.await</a> should have had the same mechanism to avoid behavioural inconsistency and this would cause implementation details of a coroutines (whether it had delegated parts of its work to its children or not) to leak to its exception handler.</p> </blockquote>  <div class="sample" data-min-compiler-version="1.3" theme="idea"> <pre>import kotlinx.coroutines.*
import java.io.*

fun main() = runBlocking {
    val handler = CoroutineExceptionHandler { _, exception -&gt;
        println("Caught $exception with suppressed ${exception.suppressed.contentToString()}")
    }
    val job = GlobalScope.launch(handler) {
        launch {
            try {
                delay(Long.MAX_VALUE)
            } finally {
                throw ArithmeticException()
            }
        }
        launch {
            delay(100)
            throw IOException()
        }
        delay(Long.MAX_VALUE)
    }
    job.join()  
}
</pre> </div> <blockquote> <p>You can get full code <a href="https://github.com/kotlin/kotlinx.coroutines/blob/master/kotlinx-coroutines-core/jvm/test/guide/example-exceptions-05.kt" target="_blank">here</a>.</p> </blockquote> <blockquote> <p>Note: This above code will work properly only on JDK7+ that supports <code>suppressed</code> exceptions</p> </blockquote> <p>The output of this code is:</p> <pre>Caught java.io.IOException with suppressed [java.lang.ArithmeticException]
</pre>  <blockquote> <p>Note, this mechanism currently works only on Java version 1.7+. Limitation on JS and Native is temporary and will be fixed in the future.</p> </blockquote> <p>Cancellation exceptions are transparent and unwrapped by default:</p> <div class="sample" data-min-compiler-version="1.3" theme="idea"> <pre>import kotlinx.coroutines.*
import java.io.*

fun main() = runBlocking {
//sampleStart
    val handler = CoroutineExceptionHandler { _, exception -&gt;
        println("Caught original $exception")
    }
    val job = GlobalScope.launch(handler) {
        val inner = launch {
            launch {
                launch {
                    throw IOException()
                }
            }
        }
        try {
            inner.join()
        } catch (e: CancellationException) {
            println("Rethrowing CancellationException with original cause")
            throw e
        }
    }
    job.join()
//sampleEnd    
}
</pre> </div> <blockquote> <p>You can get full code <a href="https://github.com/kotlin/kotlinx.coroutines/blob/master/kotlinx-coroutines-core/jvm/test/guide/example-exceptions-06.kt" target="_blank">here</a>.</p> </blockquote> <p>The output of this code is:</p> <pre>Rethrowing CancellationException with original cause
Caught original java.io.IOException
</pre>  <h2 id="supervision">Supervision</h2> <p>As we have studied before, cancellation is a bidirectional relationship propagating through the whole coroutines hierarchy. But what if unidirectional cancellation is required?</p> <p>A good example of such a requirement is a UI component with the job defined in its scope. If any of the UI's child tasks have failed, it is not always necessary to cancel (effectively kill) the whole UI component, but if UI component is destroyed (and its job is cancelled), then it is necessary to fail all child jobs as their results are no longer required.</p> <p>Another example is a server process that spawns several children jobs and needs to <em>supervise</em> their execution, tracking their failures and restarting just those children jobs that had failed.</p> <h3 id="supervision-job">Supervision job</h3> <p>For these purposes <a href="https://kotlin.github.io/kotlinx.coroutines/kotlinx-coroutines-core/kotlinx.coroutines/-supervisor-job.html" target="_blank">SupervisorJob</a> can be used. It is similar to a regular <a href="https://kotlin.github.io/kotlinx.coroutines/kotlinx-coroutines-core/kotlinx.coroutines/-job.html" target="_blank">Job</a> with the only exception that cancellation is propagated only downwards. It is easy to demonstrate with an example:</p> <div class="sample" data-highlight-only="" theme="idea"> <pre>import kotlinx.coroutines.*

fun main() = runBlocking {
    val supervisor = SupervisorJob()
    with(CoroutineScope(coroutineContext + supervisor)) {
        // launch the first child -- its exception is ignored for this example (don't do this in practice!)
        val firstChild = launch(CoroutineExceptionHandler { _, _ -&gt;  }) {
            println("First child is failing")
            throw AssertionError("First child is cancelled")
        }
        // launch the second child
        val secondChild = launch {
            firstChild.join()
            // Cancellation of the first child is not propagated to the second child
            println("First child is cancelled: ${firstChild.isCancelled}, but second one is still active")
            try {
                delay(Long.MAX_VALUE)
            } finally {
                // But cancellation of the supervisor is propagated
                println("Second child is cancelled because supervisor is cancelled")
            }
        }
        // wait until the first child fails &amp; completes
        firstChild.join()
        println("Cancelling supervisor")
        supervisor.cancel()
        secondChild.join()
    }
}
</pre> </div> <blockquote> <p>You can get full code <a href="https://github.com/kotlin/kotlinx.coroutines/blob/master/kotlinx-coroutines-core/jvm/test/guide/example-supervision-01.kt" target="_blank">here</a>.</p> </blockquote> <p>The output of this code is:</p> <pre>First child is failing
First child is cancelled: true, but second one is still active
Cancelling supervisor
Second child is cancelled because supervisor is cancelled
</pre>  <h3 id="supervision-scope">Supervision scope</h3> <p>For <em>scoped</em> concurrency <a href="https://kotlin.github.io/kotlinx.coroutines/kotlinx-coroutines-core/kotlinx.coroutines/supervisor-scope.html" target="_blank">supervisorScope</a> can be used instead of <a href="https://kotlin.github.io/kotlinx.coroutines/kotlinx-coroutines-core/kotlinx.coroutines/coroutine-scope.html" target="_blank">coroutineScope</a> for the same purpose. It propagates cancellation only in one direction and cancels all children only if it has failed itself. It also waits for all children before completion just like <a href="https://kotlin.github.io/kotlinx.coroutines/kotlinx-coroutines-core/kotlinx.coroutines/coroutine-scope.html" target="_blank">coroutineScope</a> does.</p> <div class="sample" data-highlight-only="" theme="idea"> <pre>import kotlin.coroutines.*
import kotlinx.coroutines.*

fun main() = runBlocking {
    try {
        supervisorScope {
            val child = launch {
                try {
                    println("Child is sleeping")
                    delay(Long.MAX_VALUE)
                } finally {
                    println("Child is cancelled")
                }
            }
            // Give our child a chance to execute and print using yield 
            yield()
            println("Throwing exception from scope")
            throw AssertionError()
        }
    } catch(e: AssertionError) {
        println("Caught assertion error")
    }
}
</pre> </div> <blockquote> <p>You can get full code <a href="https://github.com/kotlin/kotlinx.coroutines/blob/master/kotlinx-coroutines-core/jvm/test/guide/example-supervision-02.kt" target="_blank">here</a>.</p> </blockquote> <p>The output of this code is:</p> <pre>Child is sleeping
Throwing exception from scope
Child is cancelled
Caught assertion error
</pre>  <h3 id="exceptions-in-supervised-coroutines">Exceptions in supervised coroutines</h3> <p>Another crucial difference between regular and supervisor jobs is exception handling. Every child should handle its exceptions by itself via exception handling mechanisms. This difference comes from the fact that child's failure is not propagated to the parent.</p> <div class="sample" data-highlight-only="" theme="idea"> <pre>import kotlin.coroutines.*
import kotlinx.coroutines.*

fun main() = runBlocking {
    val handler = CoroutineExceptionHandler { _, exception -&gt; 
        println("Caught $exception") 
    }
    supervisorScope {
        val child = launch(handler) {
            println("Child throws an exception")
            throw AssertionError()
        }
        println("Scope is completing")
    }
    println("Scope is completed")
}
</pre> </div> <blockquote> <p>You can get full code <a href="https://github.com/kotlin/kotlinx.coroutines/blob/master/kotlinx-coroutines-core/jvm/test/guide/example-supervision-03.kt" target="_blank">here</a>.</p> </blockquote> <p>The output of this code is:</p> <pre>Scope is completing
Child throws an exception
Caught java.lang.AssertionError
Scope is completed
</pre>
<div class="_attribution">
  <p class="_attribution-p">
    © 2010–2019 JetBrains s.r.o.<br>Licensed under the Apache License, Version 2.0.<br>
    <a href="https://kotlinlang.org/docs/reference/coroutines/exception-handling.html" class="_attribution-link" target="_blank">https://kotlinlang.org/docs/reference/coroutines/exception-handling.html</a>
  </p>
</div>

				
			</div>
			<amp-auto-ads type="adsense"
              data-ad-client="ca-pub-2572770204602497">
</amp-auto-ads>
<ins class="adsbygoogle"
     style="display:block"
     data-ad-client="ca-pub-2572770204602497"
     data-ad-slot="1992473792"
     data-ad-format="auto"
     data-full-width-responsive="true"></ins>
<script>
     (adsbygoogle = window.adsbygoogle || []).push({});
</script>
		</div>
	</section>

	</div>
	<svg style="display:none">
		<symbol id="icon-dir"><svg viewBox="0 0 20 20"><path d="M15 10c0 .3-.305.515-.305.515l-8.56 5.303c-.625.41-1.135.106-1.135-.67V4.853c0-.777.51-1.078 1.135-.67l8.56 5.305S15 9.702 15 10z"/></svg></symbol>
	  </svg>
</body>
</html>
